Workbook

Sheet Original_Data
A1: ORIGINAL PROPOSAL BASELINE - reproduced exactly as written (spelling preserved); not modified by the model
A2: Source: 'BENEFIT REALISE Project HwU Cluster Work plan on Integrated Strategies for Resilience', Section 5 Budgeting.
A4: Activites (original wording) | B4: Planned budget in Birr | C4: Share of total | D4: Analyst note
A5: Procurument of industial inpout for Poultery house construction/renovation | B5: 40000 | C5: =B5/$B$13 -> 0.13333333 | D5: Partial support; woreda builds the house (cost-sharing).
A6: Purchase of poultery feed/ | B6: 70000 | C6: =B6/$B$13 -> 0.23333333 | D6: Text: feed 'only for one month' supplied by project.
A7: Purchase of vaccsine / medicine | B7: 12000 | C7: =B7/$B$13 -> 0.04
A8: Purchase of equipments /brooder box, watering, feeder , saw dust etc | B8: 30000 | C8: =B8/$B$13 -> 0.1
A9: Provision of trainings ( Group formation, book keeping, Poltery production management | B9: 28000 | C9: =B9/$B$13 -> 0.093333333 | D9: Project cost - not an enterprise asset.
A10: Conducting of exchange visites | B10: 20000 | C10: =B10/$B$13 -> 0.066666667 | D10: Project cost - not an enterprise asset.
A11: Purchased of day old chikens | B11: 32000 | C11: =B11/$B$13 -> 0.10666667 | D11: Number of chicks not stated.
A12: Monitoring and Evaluation | B12: 68000 | C12: =B12/$B$13 -> 0.22666667 | D12: Project cost; 22.7% of total - high for a pilot of this size.
A13: Total | B13: 300000 | D13: Stated total as written in source.
A14: Recalculated sum of line items (analytical check) | B14: =SUM(B5:B12) -> 300000
A15: Difference stated total vs sum (0 = reconciles) | B15: =B13-B14 -> 0
A17: Analytical groupings (not in source)
A18: Direct production inputs and assets (house inputs, feed, vaccine, equipment, DOC) | B18: =B5+B6+B7+B8+B11 -> 184000 | C18: =B18/$B$13 -> 0.61333333
A19: Capacity building and learning (training, exchange visits, M&E) | B19: =B9+B10+B12 -> 116000 | C19: =B19/$B$13 -> 0.38666667
A20: Per enterprise, if direct inputs split equally between 2 groups (assumption) | B20: =B18/2 -> 92000
A22: Other original facts used: 2 enterprises; 10 young female members each; 2 kebeles in 2 woredas; rearing period about two months; house by woreda; project supplies DOC, brooder boxes, feeders and feed for one month; project period 2018-2020; schedule Sep.-Aug. (year not stated).

Sheet Assumptions
A1: Youth Pullet-Rearing Enterprise (one group of 10) - Assumptions (all values in ETB unless stated)
A2: Illustrative re-costing at October 2026 prices for ONE of the two proposed youth enterprises. Blue = input; black = formula. Original proposal figures are preserved separately on the 'Original_Data' sheet and are NOT overwritten here. Values marked VERIFY are planning assumptions that must be replaced by local quotations.
A3: Active scenario (1 = Base, 2 = Downside, 3 = Upside) | C3: 1 | D3: =CHOOSE($C$3,"Base","Downside","Upside") -> Base
A4: How to use: change the yellow scenario cell (C3) or any blue input; every statement recalculates. Replace VERIFY values with local quotations.
A5: Assumption | B5: Unit | C5: Base | D5: Downside | E5: Upside | F5: Active | G5: Status / source / note
A6: 1. Timing (model month 1 = 'Sep.' column of the original activity schedule; year not stated in source)
A7: Month poultry house and equipment are ready | B7: month | C7: 3 | D7: 4 | E7: 3 | F7: =CHOOSE($C$3,C7,D7,E7) -> 3 | G7: Assumption. Original Gantt cells are blank; sequence (selection > site > construction > training > inputs) implies construction precedes DOC.
A8: Month of first day-old-chick (DOC) placement | B8: month | C8: 5 | D8: 6 | E8: 5 | F8: =CHOOSE($C$3,C8,D8,E8) -> 5 | G8: Assumption (original: 'Availing day old chicken' listed after construction/training; timing blank).
A9: Months between batch placements | B9: months | C9: 3 | D9: 4 | E9: 3 | F9: =CHOOSE($C$3,C9,D9,E9) -> 3 | G9: Assumption: ~2 months rearing (original: 'about two months') + ~1 month sale, cleaning, rest. Base = 4 batches/yr.
A10: Month member equity is paid in | B10: month | C10: 1 | D10: 1 | E10: 1 | F10: =CHOOSE($C$3,C10,D10,E10) -> 1 | G10: Assumption.
A11: 2. Production
A12: DOC placed per batch | B12: birds | C12: 500 | D12: 500 | E12: 500 | F12: =CHOOSE($C$3,C12,D12,E12) -> 500 | G12: ILLUSTRATIVE planning scale - the original proposal does not state chick numbers. ~25-30 m2 brooding/rearing floor at 15-20 birds/m2 to 8 weeks. VERIFY
A13: Mortality to sale (~8 weeks) | B13: % of placed | C13: 0.1 | D13: 0.2 | E13: 0.07 | F13: =CHOOSE($C$3,C13,D13,E13) -> 0.1 | G13: Assumption. On-farm Koekoek trial in South Omo reported 73.1% survival to 45 days (farmer management); managed brooding should do better. VERIFY
A14: Feed per bird placed, 0-8 weeks (incl. wastage) | B14: kg | C14: 1.7 | D14: 1.8 | E14: 1.6 | F14: =CHOOSE($C$3,C14,D14,E14) -> 1.7 | G14: Assumption from typical layer/dual-purpose pullet growth curves; confirm with breed guide (Lohmann Brown / Koekoek) and supplier. VERIFY
A15: Share of batch feed used in placement month | B15: % | C15: 0.4 | D15: 0.4 | E15: 0.4 | F15: =CHOOSE($C$3,C15,D15,E15) -> 0.4 | G15: Assumption (intake rises with age).
A16: 3. Prices and variable costs (PY1 prices; escalated annually)
A17: Day-old chick price | B17: ETB/chick | C17: 100 | D17: 120 | E17: 90 | F17: =CHOOSE($C$3,C17,D17,E17) -> 100 | G17: Assumption. Published 2025-26 figures conflict (ETB 5-22 to 75); pre-2022 press reported ~ETB 50. Obtain quotes from DZARC (EIAR) and private hatcheries. VERIFY
A18: Starter/grower feed price | B18: ETB/kg | C18: 80 | D18: 95 | E18: 75 | F18: =CHOOSE($C$3,C18,D18,E18) -> 80 | G18: Assumption. 2022 field data: layer feed mean ETB 2,695/qt (26.95/kg); 2026 vendor web page: ETB 8,800/qt (unverified). Birr has depreciated sharply since July 2024. VERIFY
A19: Vaccines and medication | B19: ETB/bird placed | C19: 12 | D19: 15 | E19: 10 | F19: =CHOOSE($C$3,C19,D19,E19) -> 12 | G19: Assumption (NVI vaccines: Marek's at hatchery, NCD, Gumboro, fowl pox). VERIFY
A20: Brooding energy (electricity/backup) | B20: ETB/batch | C20: 3000 | D20: 4000 | E20: 2500 | F20: =CHOOSE($C$3,C20,D20,E20) -> 3000 | G20: Assumption. VERIFY
A21: Litter (sawdust) and disinfectant | B21: ETB/batch | C21: 1500 | D21: 2000 | E21: 1200 | F21: =CHOOSE($C$3,C21,D21,E21) -> 1500 | G21: Assumption (original budget line mentions saw dust). VERIFY
A22: Selling and transport | B22: ETB/batch | C22: 4000 | D22: 6000 | E22: 3500 | F22: =CHOOSE($C$3,C22,D22,E22) -> 4000 | G22: Assumption. VERIFY
A23: Selling price of ~8-week pullet | B23: ETB/bird | C23: 450 | D23: 380 | E23: 520 | F23: =CHOOSE($C$3,C23,D23,E23) -> 450 | G23: Assumption. Only located 2026 data point: one online listing of a vaccinated 2-month Bovans Brown at ETB 710 (Addis, undated); 2020 report: ETB 100-120. Rural PSNP buyers' willingness to pay must be tested. VERIFY
A24: Share of sales collected in month of sale | B24: % | C24: 0.6 | D24: 0.4 | E24: 0.8 | F24: =CHOOSE($C$3,C24,D24,E24) -> 0.6 | G24: Assumption; remainder collected the following month (institutional/NGO buyers pay on invoice).
A25: Annual selling-price escalation | B25: %/yr | C25: 0.12 | D25: 0.08 | E25: 0.12 | F25: =CHOOSE($C$3,C25,D25,E25) -> 0.12 | G25: Assumption. CPI inflation 15.3% (Jul 2026); NBE expects decline. Downside: prices lag costs.
A26: Annual cost escalation | B26: %/yr | C26: 0.12 | D26: 0.15 | E26: 0.12 | F26: =CHOOSE($C$3,C26,D26,E26) -> 0.12 | G26: Assumption (see above).
A27: 4. Fixed operating costs (PY1 prices)
A28: Cash allowance for members on duty | B28: ETB/month | C28: 9000 | D28: 9000 | E28: 9000 | F28: =CHOOSE($C$3,C28,D28,E28) -> 9000 | G28: Assumption: 3 members on rotating duty x ETB 3,000/month. Remaining members are unpaid owners (see memo).
A29: Imputed value of unpaid member time (memo only) | B29: ETB/month | C29: 7000 | D29: 7000 | E29: 7000 | F29: =CHOOSE($C$3,C29,D29,E29) -> 7000 | G29: Assumption: 7 members x 4 days/month x ETB 250/day. Not a cash cost; shown to reveal economic return to labour. VERIFY
A30: Water | B30: ETB/month | C30: 600 | D30: 800 | E30: 600 | F30: =CHOOSE($C$3,C30,D30,E30) -> 600 | G30: Assumption. VERIFY
A31: Bookkeeping, phone, stationery, bank charges | B31: ETB/month | C31: 800 | D31: 800 | E31: 800 | F31: =CHOOSE($C$3,C31,D31,E31) -> 800 | G31: Assumption.
A32: Maintenance | B32: % of asset cost/yr | C32: 0.05 | D32: 0.05 | E32: 0.05 | F32: =CHOOSE($C$3,C32,D32,E32) -> 0.05 | G32: Assumption.
A33: Legal registration (one-off, month 2) | B33: ETB | C33: 3000 | D33: 3000 | E33: 3000 | F33: =CHOOSE($C$3,C33,D33,E33) -> 3000 | G33: Assumption; group organised as cooperative/association via woreda cooperative office. VERIFY
A34: Annual licence/renewal and audit | B34: ETB/yr | C34: 2000 | D34: 2000 | E34: 2000 | F34: =CHOOSE($C$3,C34,D34,E34) -> 2000 | G34: Assumption. VERIFY
A35: 5. Investment and grant/in-kind contributions
A36: Poultry house - full value (woreda in-kind incl. project materials) | B36: ETB | C36: 250000 | D36: 250000 | E36: 250000 | F36: =CHOOSE($C$3,C36,D36,E36) -> 250000 | G36: Assumption for valuing the woreda contribution (~35 m2 simple house). Original: woreda builds house; project supplies corrugated iron and nails. VERIFY
A37: Equipment (brooders, feeders, drinkers, heaters, scale) at 2026 prices | B37: ETB | C37: 45000 | D37: 50000 | E37: 45000 | F37: =CHOOSE($C$3,C37,D37,E37) -> 45000 | G37: Assumption. VERIFY
A38: Project grant: equipment (original ETB 30,000 / 2 groups) | B38: ETB | C38: 15000 | D38: 15000 | E38: 15000 | F38: =CHOOSE($C$3,C38,D38,E38) -> 15000 | G38: ORIGINAL budget line split equally between the two enterprises - the equal split is an analytical assumption.
A39: Project grant: first-batch inputs (DOC 16,000 + feed 35,000 + vaccine 6,000) | B39: ETB | C39: 57000 | D39: 57000 | E39: 57000 | F39: =CHOOSE($C$3,C39,D39,E39) -> 57000 | G39: ORIGINAL budget lines (32,000; 70,000; 12,000) split equally. Original: feed 'only for one month'.
A40: Useful life - house | B40: years | C40: 10 | D40: 10 | E40: 10 | F40: =CHOOSE($C$3,C40,D40,E40) -> 10 | G40: Assumption.
...

Sheet Monthly
A1: Youth Pullet-Rearing Enterprise (one group of 10) - Monthly engine (60 months). Month 1 = first month of the original Sep.-Aug. schedule; year not stated in source.
A3: Model month no. | C3: 1 | D3: 2 | E3: 3 | F3: 4 | G3: 5 | H3: 6 | I3: 7 | J3: 8 | K3: 9 | L3: 10 | M3: 11 | N3: 12 | O3: 13 | P3: 14 | Q3: 15 | R3: 16 | S3: 17 | T3: 18 | U3: 19 | V3: 20 | W3: 21 | X3: 22 | Y3: 23 | Z3: 24 | AA3: 25 | AB3: 26 | AC3: 27 | AD3: 28 | AE3: 29 | AF3: 30 | AG3: 31 | AH3: 32 | AI3: 33 | AJ3: 34 | AK3: 35 | AL3: 36 | AM3: 37 | AN3: 38 | AO3: 39 | AP3: 40 | AQ3: 41 | AR3: 42 | AS3: 43 | AT3: 44 | AU3: 45 | AV3: 46 | AW3: 47 | AX3: 48 | AY3: 49 | AZ3: 50 | BA3: 51 | BB3: 52 | BC3: 53 | BD3: 54 | BE3: 55 | BF3: 56 | BG3: 57 | BH3: 58 | BI3: 59 | BJ3: 60
A4: Project year (PY) | C4: =INT((C3-1)/12)+1 -> 1 | D4: =INT((D3-1)/12)+1 -> 1 | E4: =INT((E3-1)/12)+1 -> 1 | F4: =INT((F3-1)/12)+1 -> 1 | G4: =INT((G3-1)/12)+1 -> 1 | H4: =INT((H3-1)/12)+1 -> 1 | I4: =INT((I3-1)/12)+1 -> 1 | J4: =INT((J3-1)/12)+1 -> 1 | ... BJ4: =INT((BJ3-1)/12)+1 -> 5
A5: Calendar month label (year to be confirmed) | C5: Sep | D5: Oct | E5: Nov | F5: Dec | G5: Jan | H5: Feb | I5: Mar | J5: Apr | K5: May | L5: Jun | M5: Jul | N5: Aug | O5: Sep | P5: Oct | Q5: Nov | R5: Dec | S5: Jan | T5: Feb | U5: Mar | V5: Apr | W5: May | X5: Jun | Y5: Jul | Z5: Aug | AA5: Sep | AB5: Oct | AC5: Nov | AD5: Dec | AE5: Jan | AF5: Feb | AG5: Mar | AH5: Apr | AI5: May | AJ5: Jun | AK5: Jul | AL5: Aug | AM5: Sep | AN5: Oct | AO5: Nov | AP5: Dec | AQ5: Jan | AR5: Feb | AS5: Mar | AT5: Apr | AU5: May | AV5: Jun | AW5: Jul | AX5: Aug | AY5: Sep | AZ5: Oct | BA5: Nov | BB5: Dec | BC5: Jan | BD5: Feb | BE5: Mar | BF5: Apr | BG5: May | BH5: Jun | BI5: Jul | BJ5: Aug
A6: ESCALATION
A7: Price index | C7: =(1+Assumptions!$F$25)^(C$4-1) -> 1 | D7: =(1+Assumptions!$F$25)^(D$4-1) -> 1 | E7: =(1+Assumptions!$F$25)^(E$4-1) -> 1 | F7: =(1+Assumptions!$F$25)^(F$4-1) -> 1 | G7: =(1+Assumptions!$F$25)^(G$4-1) -> 1 | H7: =(1+Assumptions!$F$25)^(H$4-1) -> 1 | I7: =(1+Assumptions!$F$25)^(I$4-1) -> 1 | J7: =(1+Assumptions!$F$25)^(J$4-1) -> 1 | ... BJ7: =(1+Assumptions!$F$25)^(BJ$4-1) -> 1.5735194
A8: Cost index | C8: =(1+Assumptions!$F$26)^(C$4-1) -> 1 | D8: =(1+Assumptions!$F$26)^(D$4-1) -> 1 | E8: =(1+Assumptions!$F$26)^(E$4-1) -> 1 | F8: =(1+Assumptions!$F$26)^(F$4-1) -> 1 | G8: =(1+Assumptions!$F$26)^(G$4-1) -> 1 | H8: =(1+Assumptions!$F$26)^(H$4-1) -> 1 | I8: =(1+Assumptions!$F$26)^(I$4-1) -> 1 | J8: =(1+Assumptions!$F$26)^(J$4-1) -> 1 | ... BJ8: =(1+Assumptions!$F$26)^(BJ$4-1) -> 1.5735194
A9: PRODUCTION
A10: Batch placed this month (1 = yes) | C10: =IF(AND(C$3>=Assumptions!$F$8,MOD(C$3-Assumptions!$F$8,Assumptions!$F$9)=0),1,0) -> 0 | D10: =IF(AND(D$3>=Assumptions!$F$8,MOD(D$3-Assumptions!$F$8,Assumptions!$F$9)=0),1,0) -> 0 | E10: =IF(AND(E$3>=Assumptions!$F$8,MOD(E$3-Assumptions!$F$8,Assumptions!$F$9)=0),1,0) -> 0 | F10: =IF(AND(F$3>=Assumptions!$F$8,MOD(F$3-Assumptions!$F$8,Assumptions!$F$9)=0),1,0) -> 0 | G10: =IF(AND(G$3>=Assumptions!$F$8,MOD(G$3-Assumptions!$F$8,Assumptions!$F$9)=0),1,0) -> 1 | H10: =IF(AND(H$3>=Assumptions!$F$8,MOD(H$3-Assumptions!$F$8,Assumptions!$F$9)=0),1,0) -> 0 | I10: =IF(AND(I$3>=Assumptions!$F$8,MOD(I$3-Assumptions!$F$8,Assumptions!$F$9)=0),1,0) -> 0 | J10: =IF(AND(J$3>=Assumptions!$F$8,MOD(J$3-Assumptions!$F$8,Assumptions!$F$9)=0),1,0) -> 1 | ... BJ10: =IF(AND(BJ$3>=Assumptions!$F$8,MOD(BJ$3-Assumptions!$F$8,Assumptions!$F$9)=0),1,0) -> 0
A11: Day-old chicks placed | B11: birds | C11: =C10*Assumptions!$F$12 -> 0 | D11: =D10*Assumptions!$F$12 -> 0 | E11: =E10*Assumptions!$F$12 -> 0 | F11: =F10*Assumptions!$F$12 -> 0 | G11: =G10*Assumptions!$F$12 -> 500 | H11: =H10*Assumptions!$F$12 -> 0 | I11: =I10*Assumptions!$F$12 -> 0 | J11: =J10*Assumptions!$F$12 -> 500 | ... BJ11: =BJ10*Assumptions!$F$12 -> 0
A12: Pullets sold (placed last month x survival) | B12: birds | C12: =0 -> 0 | D12: =C11*(1-Assumptions!$F$13) -> 0 | E12: =D11*(1-Assumptions!$F$13) -> 0 | F12: =E11*(1-Assumptions!$F$13) -> 0 | G12: =F11*(1-Assumptions!$F$13) -> 0 | H12: =G11*(1-Assumptions!$F$13) -> 450 | I12: =H11*(1-Assumptions!$F$13) -> 0 | J12: =I11*(1-Assumptions!$F$13) -> 0 | K12: =J11*(1-Assumptions!$F$13) -> 450 | ... BJ12: =BI11*(1-Assumptions!$F$13) -> 450
A13: REVENUE AND COLLECTIONS
A14: Pullet sales | C14: =C12*Assumptions!$F$23*C7 -> 0 | D14: =D12*Assumptions!$F$23*D7 -> 0 | E14: =E12*Assumptions!$F$23*E7 -> 0 | F14: =F12*Assumptions!$F$23*F7 -> 0 | G14: =G12*Assumptions!$F$23*G7 -> 0 | H14: =H12*Assumptions!$F$23*H7 -> 202500 | I14: =I12*Assumptions!$F$23*I7 -> 0 | J14: =J12*Assumptions!$F$23*J7 -> 0 | ... BJ14: =BJ12*Assumptions!$F$23*BJ7 -> 318637.67
A15: Cash collected | C15: =C14*Assumptions!$F$24 -> 0 | D15: =D14*Assumptions!$F$24+C14*(1-Assumptions!$F$24) -> 0 | E15: =E14*Assumptions!$F$24+D14*(1-Assumptions!$F$24) -> 0 | F15: =F14*Assumptions!$F$24+E14*(1-Assumptions!$F$24) -> 0 | G15: =G14*Assumptions!$F$24+F14*(1-Assumptions!$F$24) -> 0 | H15: =H14*Assumptions!$F$24+G14*(1-Assumptions!$F$24) -> 121500 | I15: =I14*Assumptions!$F$24+H14*(1-Assumptions!$F$24) -> 81000 | J15: =J14*Assumptions!$F$24+I14*(1-Assumptions!$F$24) -> 0 | K15: =K14*Assumptions!$F$24+J14*(1-Assumptions!$F$24) -> 121500 | ... BJ15: =BJ14*Assumptions!$F$24+BI14*(1-Assumptions!$F$24) -> 191182.6
A16: Receivables (end of month) | C16: =C14-C15 -> 0 | D16: =C16+D14-D15 -> 0 | E16: =D16+E14-E15 -> 0 | F16: =E16+F14-F15 -> 0 | G16: =F16+G14-G15 -> 0 | H16: =G16+H14-H15 -> 81000 | I16: =H16+I14-I15 -> 0 | J16: =I16+J14-J15 -> 0 | K16: =J16+K14-K15 -> 81000 | ... BJ16: =BI16+BJ14-BJ15 -> 127455.07
A17: VARIABLE COSTS
A18: Day-old chicks | C18: =C11*Assumptions!$F$17*C8 -> 0 | D18: =D11*Assumptions!$F$17*D8 -> 0 | E18: =E11*Assumptions!$F$17*E8 -> 0 | F18: =F11*Assumptions!$F$17*F8 -> 0 | G18: =G11*Assumptions!$F$17*G8 -> 50000 | H18: =H11*Assumptions!$F$17*H8 -> 0 | I18: =I11*Assumptions!$F$17*I8 -> 0 | J18: =J11*Assumptions!$F$17*J8 -> 50000 | ... BJ18: =BJ11*Assumptions!$F$17*BJ8 -> 0
A19: Feed | C19: =C11*Assumptions!$F$15*Assumptions!$F$14*Assumptions!$F$18*C8 -> 0 | D19: =(D11*Assumptions!$F$15+C11*(1-Assumptions!$F$15))*Assumptions!$F$14*Assumptions!$F$18*D8 -> 0 | E19: =(E11*Assumptions!$F$15+D11*(1-Assumptions!$F$15))*Assumptions!$F$14*Assumptions!$F$18*E8 -> 0 | F19: =(F11*Assumptions!$F$15+E11*(1-Assumptions!$F$15))*Assumptions!$F$14*Assumptions!$F$18*F8 -> 0 | G19: =(G11*Assumptions!$F$15+F11*(1-Assumptions!$F$15))*Assumptions!$F$14*Assumptions!$F$18*G8 -> 27200 | H19: =(H11*Assumptions!$F$15+G11*(1-Assumptions!$F$15))*Assumptions!$F$14*Assumptions!$F$18*H8 -> 40800 | I19: =(I11*Assumptions!$F$15+H11*(1-Assumptions!$F$15))*Assumptions!$F$14*Assumptions!$F$18*I8 -> 0 | J19: =(J11*Assumptions!$F$15+I11*(1-Assumptions!$F$15))*Assumptions!$F$14*Assumptions!$F$18*J8 -> 27200 | K19: =(K11*Assumptions!$F$15+J11*(1-Assumptions!$F$15))*Assumptions!$F$14*Assumptions!$F$18*K8 -> 40800 | ... BJ19: =(BJ11*Assumptions!$F$15+BI11*(1-Assumptions!$F$15))*Assumptions!$F$14*Assumptions!$F$18*BJ8 -> 64199.59
A20: Vaccines and medication | C20: =C11*Assumptions!$F$19*C8 -> 0 | D20: =D11*Assumptions!$F$19*D8 -> 0 | E20: =E11*Assumptions!$F$19*E8 -> 0 | F20: =F11*Assumptions!$F$19*F8 -> 0 | G20: =G11*Assumptions!$F$19*G8 -> 6000 | H20: =H11*Assumptions!$F$19*H8 -> 0 | I20: =I11*Assumptions!$F$19*I8 -> 0 | J20: =J11*Assumptions!$F$19*J8 -> 6000 | ... BJ20: =BJ11*Assumptions!$F$19*BJ8 -> 0
A21: Brooding energy | C21: =C10*Assumptions!$F$20/2*C8 -> 0 | D21: =(D10+C10)*Assumptions!$F$20/2*D8 -> 0 | E21: =(E10+D10)*Assumptions!$F$20/2*E8 -> 0 | F21: =(F10+E10)*Assumptions!$F$20/2*F8 -> 0 | G21: =(G10+F10)*Assumptions!$F$20/2*G8 -> 1500 | H21: =(H10+G10)*Assumptions!$F$20/2*H8 -> 1500 | I21: =(I10+H10)*Assumptions!$F$20/2*I8 -> 0 | J21: =(J10+I10)*Assumptions!$F$20/2*J8 -> 1500 | K21: =(K10+J10)*Assumptions!$F$20/2*K8 -> 1500 | ... BJ21: =(BJ10+BI10)*Assumptions!$F$20/2*BJ8 -> 2360.279
A22: Litter and disinfectant | C22: =C10*Assumptions!$F$21*C8 -> 0 | D22: =D10*Assumptions!$F$21*D8 -> 0 | E22: =E10*Assumptions!$F$21*E8 -> 0 | F22: =F10*Assumptions!$F$21*F8 -> 0 | G22: =G10*Assumptions!$F$21*G8 -> 1500 | H22: =H10*Assumptions!$F$21*H8 -> 0 | I22: =I10*Assumptions!$F$21*I8 -> 0 | J22: =J10*Assumptions!$F$21*J8 -> 1500 | ... BJ22: =BJ10*Assumptions!$F$21*BJ8 -> 0
A23: Selling and transport | C23: =0 -> 0 | D23: =C10*Assumptions!$F$22*D8 -> 0 | E23: =D10*Assumptions!$F$22*E8 -> 0 | F23: =E10*Assumptions!$F$22*F8 -> 0 | G23: =F10*Assumptions!$F$22*G8 -> 0 | H23: =G10*Assumptions!$F$22*H8 -> 4000 | I23: =H10*Assumptions!$F$22*I8 -> 0 | J23: =I10*Assumptions!$F$22*J8 -> 0 | K23: =J10*Assumptions!$F$22*K8 -> 4000 | ... BJ23: =BI10*Assumptions!$F$22*BJ8 -> 6294.0774
A24: Total variable costs | C24: =C18+C19+C20+C21+C22+C23 -> 0 | D24: =D18+D19+D20+D21+D22+D23 -> 0 | E24: =E18+E19+E20+E21+E22+E23 -> 0 | F24: =F18+F19+F20+F21+F22+F23 -> 0 | G24: =G18+G19+G20+G21+G22+G23 -> 86200 | H24: =H18+H19+H20+H21+H22+H23 -> 46300 | I24: =I18+I19+I20+I21+I22+I23 -> 0 | J24: =J18+J19+J20+J21+J22+J23 -> 86200 | ... BJ24: =BJ18+BJ19+BJ20+BJ21+BJ22+BJ23 -> 72853.946
A25: Of which funded by project in-kind inputs (non-cash) | C25: =IF(C$3=Assumptions!$F$8,MIN(Assumptions!$F$39,C18+C19+C20),0) -> 0 | D25: =IF(D$3=Assumptions!$F$8,MIN(Assumptions!$F$39,D18+D19+D20),0) -> 0 | E25: =IF(E$3=Assumptions!$F$8,MIN(Assumptions!$F$39,E18+E19+E20),0) -> 0 | F25: =IF(F$3=Assumptions!$F$8,MIN(Assumptions!$F$39,F18+F19+F20),0) -> 0 | G25: =IF(G$3=Assumptions!$F$8,MIN(Assumptions!$F$39,G18+G19+G20),0) -> 57000 | H25: =IF(H$3=Assumptions!$F$8,MIN(Assumptions!$F$39,H18+H19+H20),0) -> 0 | I25: =IF(I$3=Assumptions!$F$8,MIN(Assumptions!$F$39,I18+I19+I20),0) -> 0 | J25: =IF(J$3=Assumptions!$F$8,MIN(Assumptions!$F$39,J18+J19+J20),0) -> 0 | ... BJ25: =IF(BJ$3=Assumptions!$F$8,MIN(Assumptions!$F$39,BJ18+BJ19+BJ20),0) -> 0
A26: Variable costs paid in cash | C26: =C24-C25 -> 0 | D26: =D24-D25 -> 0 | E26: =E24-E25 -> 0 | F26: =F24-F25 -> 0 | G26: =G24-G25 -> 29200 | H26: =H24-H25 -> 46300 | I26: =I24-I25 -> 0 | J26: =J24-J25 -> 86200 | ... BJ26: =BJ24-BJ25 -> 72853.946
A27: FIXED COSTS
A28: Operating (1 = from month before first placement) | C28: =IF(C$3>=Assumptions!$F$8-1,1,0) -> 0 | D28: =IF(D$3>=Assumptions!$F$8-1,1,0) -> 0 | E28: =IF(E$3>=Assumptions!$F$8-1,1,0) -> 0 | F28: =IF(F$3>=Assumptions!$F$8-1,1,0) -> 1 | G28: =IF(G$3>=Assumptions!$F$8-1,1,0) -> 1 | H28: =IF(H$3>=Assumptions!$F$8-1,1,0) -> 1 | I28: =IF(I$3>=Assumptions!$F$8-1,1,0) -> 1 | J28: =IF(J$3>=Assumptions!$F$8-1,1,0) -> 1 | ... BJ28: =IF(BJ$3>=Assumptions!$F$8-1,1,0) -> 1
A29: Member duty allowances | C29: =C28*Assumptions!$F$28*C8 -> 0 | D29: =D28*Assumptions!$F$28*D8 -> 0 | E29: =E28*Assumptions!$F$28*E8 -> 0 | F29: =F28*Assumptions!$F$28*F8 -> 9000 | G29: =G28*Assumptions!$F$28*G8 -> 9000 | H29: =H28*Assumptions!$F$28*H8 -> 9000 | I29: =I28*Assumptions!$F$28*I8 -> 9000 | J29: =J28*Assumptions!$F$28*J8 -> 9000 | ... BJ29: =BJ28*Assumptions!$F$28*BJ8 -> 14161.674
A30: Water | C30: =C28*Assumptions!$F$30*C8 -> 0 | D30: =D28*Assumptions!$F$30*D8 -> 0 | E30: =E28*Assumptions!$F$30*E8 -> 0 | F30: =F28*Assumptions!$F$30*F8 -> 600 | G30: =G28*Assumptions!$F$30*G8 -> 600 | H30: =H28*Assumptions!$F$30*H8 -> 600 | I30: =I28*Assumptions!$F$30*I8 -> 600 | J30: =J28*Assumptions!$F$30*J8 -> 600 | ... BJ30: =BJ28*Assumptions!$F$30*BJ8 -> 944.11162
A31: Administration | C31: =C28*Assumptions!$F$31*C8 -> 0 | D31: =D28*Assumptions!$F$31*D8 -> 0 | E31: =E28*Assumptions!$F$31*E8 -> 0 | F31: =F28*Assumptions!$F$31*F8 -> 800 | G31: =G28*Assumptions!$F$31*G8 -> 800 | H31: =H28*Assumptions!$F$31*H8 -> 800 | I31: =I28*Assumptions!$F$31*I8 -> 800 | J31: =J28*Assumptions!$F$31*J8 -> 800 | ... BJ31: =BJ28*Assumptions!$F$31*BJ8 -> 1258.8155
A32: Maintenance | C32: =IF(C$3>Assumptions!$F$7,(Assumptions!$F$36+Assumptions!$F$37)*Assumptions!$F$32/12*C8,0) -> 0 | D32: =IF(D$3>Assumptions!$F$7,(Assumptions!$F$36+Assumptions!$F$37)*Assumptions!$F$32/12*D8,0) -> 0 | E32: =IF(E$3>Assumptions!$F$7,(Assumptions!$F$36+Assumptions!$F$37)*Assumptions!$F$32/12*E8,0) -> 0 | F32: =IF(F$3>Assumptions!$F$7,(Assumptions!$F$36+Assumptions!$F$37)*Assumptions!$F$32/12*F8,0) -> 1229.1667 | G32: =IF(G$3>Assumptions!$F$7,(Assumptions!$F$36+Assumptions!$F$37)*Assumptions!$F$32/12*G8,0) -> 1229.1667 | H32: =IF(H$3>Assumptions!$F$7,(Assumptions!$F$36+Assumptions!$F$37)*Assumptions!$F$32/12*H8,0) -> 1229.1667 | I32: =IF(I$3>Assumptions!$F$7,(Assumptions!$F$36+Assumptions!$F$37)*Assumptions!$F$32/12*I8,0) -> 1229.1667 | J32: =IF(J$3>Assumptions!$F$7,(Assumptions!$F$36+Assumptions!$F$37)*Assumptions!$F$32/12*J8,0) -> 1229.1667 | ... BJ32: =IF(BJ$3>Assumptions!$F$7,(Assumptions!$F$36+Assumptions!$F$37)*Assumptions!$F$32/12*BJ8,0) -> 1934.1175
A33: Registration and licences | C33: =IF(C$3=2,Assumptions!$F$33,0)+IF(AND(C$3>12,MOD(C$3,12)=2),Assumptions!$F$34*C8,0) -> 0 | D33: =IF(D$3=2,Assumptions!$F$33,0)+IF(AND(D$3>12,MOD(D$3,12)=2),Assumptions!$F$34*D8,0) -> 3000 | E33: =IF(E$3=2,Assumptions!$F$33,0)+IF(AND(E$3>12,MOD(E$3,12)=2),Assumptions!$F$34*E8,0) -> 0 | F33: =IF(F$3=2,Assumptions!$F$33,0)+IF(AND(F$3>12,MOD(F$3,12)=2),Assumptions!$F$34*F8,0) -> 0 | G33: =IF(G$3=2,Assumptions!$F$33,0)+IF(AND(G$3>12,MOD(G$3,12)=2),Assumptions!$F$34*G8,0) -> 0 | H33: =IF(H$3=2,Assumptions!$F$33,0)+IF(AND(H$3>12,MOD(H$3,12)=2),Assumptions!$F$34*H8,0) -> 0 | I33: =IF(I$3=2,Assumptions!$F$33,0)+IF(AND(I$3>12,MOD(I$3,12)=2),Assumptions!$F$34*I8,0) -> 0 | J33: =IF(J$3=2,Assumptions!$F$33,0)+IF(AND(J$3>12,MOD(J$3,12)=2),Assumptions!$F$34*J8,0) -> 0 | ... BJ33: =IF(BJ$3=2,Assumptions!$F$33,0)+IF(AND(BJ$3>12,MOD(BJ$3,12)=2),Assumptions!$F$34*BJ8,0) -> 0
A34: Total fixed costs | C34: =C29+C30+C31+C32+C33 -> 0 | D34: =D29+D30+D31+D32+D33 -> 3000 | E34: =E29+E30+E31+E32+E33 -> 0 | F34: =F29+F30+F31+F32+F33 -> 11629.167 | G34: =G29+G30+G31+G32+G33 -> 11629.167 | H34: =H29+H30+H31+H32+H33 -> 11629.167 | I34: =I29+I30+I31+I32+I33 -> 11629.167 | J34: =J29+J30+J31+J32+J33 -> 11629.167 | ... BJ34: =BJ29+BJ30+BJ31+BJ32+BJ33 -> 18298.719
A35: Memo: imputed unpaid member labour | C35: =C28*Assumptions!$F$29*C8 -> 0 | D35: =D28*Assumptions!$F$29*D8 -> 0 | E35: =E28*Assumptions!$F$29*E8 -> 0 | F35: =F28*Assumptions!$F$29*F8 -> 7000 | G35: =G28*Assumptions!$F$29*G8 -> 7000 | H35: =H28*Assumptions!$F$29*H8 -> 7000 | I35: =I28*Assumptions!$F$29*I8 -> 7000 | J35: =J28*Assumptions!$F$29*J8 -> 7000 | ... BJ35: =BJ28*Assumptions!$F$29*BJ8 -> 11014.636
A36: EBITDA excluding grants | C36: =C14-C24-C34 -> 0 | D36: =D14-D24-D34 -> -3000 | E36: =E14-E24-E34 -> 0 | F36: =F14-F24-F34 -> -11629.167 | G36: =G14-G24-G34 -> -97829.167 | H36: =H14-H24-H34 -> 144570.83 | I36: =I14-I24-I34 -> -11629.167 | J36: =J14-J24-J34 -> -97829.167 | ... BJ36: =BJ14-BJ24-BJ34 -> 227485.01
A37: INVESTMENT
A38: Capital expenditure (full value) | C38: =IF(C$3=Assumptions!$F$7,Assumptions!$F$36+Assumptions!$F$37,0) -> 0 | D38: =IF(D$3=Assumptions!$F$7,Assumptions!$F$36+Assumptions!$F$37,0) -> 0 | E38: =IF(E$3=Assumptions!$F$7,Assumptions!$F$36+Assumptions!$F$37,0) -> 295000 | F38: =IF(F$3=Assumptions!$F$7,Assumptions!$F$36+Assumptions!$F$37,0) -> 0 | G38: =IF(G$3=Assumptions!$F$7,Assumptions!$F$36+Assumptions!$F$37,0) -> 0 | H38: =IF(H$3=Assumptions!$F$7,Assumptions!$F$36+Assumptions!$F$37,0) -> 0 | I38: =IF(I$3=Assumptions!$F$7,Assumptions!$F$36+Assumptions!$F$37,0) -> 0 | J38: =IF(J$3=Assumptions!$F$7,Assumptions!$F$36+Assumptions!$F$37,0) -> 0 | ... BJ38: =IF(BJ$3=Assumptions!$F$7,Assumptions!$F$36+Assumptions!$F$37,0) -> 0
A39: Of which in-kind / grant-funded | C39: =IF(C$3=Assumptions!$F$7,Assumptions!$F$36+Assumptions!$F$38,0) -> 0 | D39: =IF(D$3=Assumptions!$F$7,Assumptions!$F$36+Assumptions!$F$38,0) -> 0 | E39: =IF(E$3=Assumptions!$F$7,Assumptions!$F$36+Assumptions!$F$38,0) -> 265000 | F39: =IF(F$3=Assumptions!$F$7,Assumptions!$F$36+Assumptions!$F$38,0) -> 0 | G39: =IF(G$3=Assumptions!$F$7,Assumptions!$F$36+Assumptions!$F$38,0) -> 0 | H39: =IF(H$3=Assumptions!$F$7,Assumptions!$F$36+Assumptions!$F$38,0) -> 0 | I39: =IF(I$3=Assumptions!$F$7,Assumptions!$F$36+Assumptions!$F$38,0) -> 0 | J39: =IF(J$3=Assumptions!$F$7,Assumptions!$F$36+Assumptions!$F$38,0) -> 0 | ... BJ39: =IF(BJ$3=Assumptions!$F$7,Assumptions!$F$36+Assumptions!$F$38,0) -> 0
A40: Depreciation | C40: =IF(C$3>Assumptions!$F$7,Assumptions!$F$36/(Assumptions!$F$40*12)+IF(C$3<=Assumptions!$F$7+Assumptions!$F$41*12,Assumptions!$F$37/(Assumptions!$F$41*12),0),0) -> 0 | D40: =IF(D$3>Assumptions!$F$7,Assumptions!$F$36/(Assumptions!$F$40*12)+IF(D$3<=Assumptions!$F$7+Assumptions!$F$41*12,Assumptions!$F$37/(Assumptions!$F$41*12),0),0) -> 0 | E40: =IF(E$3>Assumptions!$F$7,Assumptions!$F$36/(Assumptions!$F$40*12)+IF(E$3<=Assumptions!$F$7+Assumptions!$F$41*12,Assumptions!$F$37/(Assumptions!$F$41*12),0),0) -> 0 | F40: =IF(F$3>Assumptions!$F$7,Assumptions!$F$36/(Assumptions!$F$40*12)+IF(F$3<=Assumptions!$F$7+Assumptions!$F$41*12,Assumptions!$F$37/(Assumptions!$F$41*12),0),0) -> 2833.3333 | G40: =IF(G$3>Assumptions!$F$7,Assumptions!$F$36/(Assumptions!$F$40*12)+IF(G$3<=Assumptions!$F$7+Assumptions!$F$41*12,Assumptions!$F$37/(Assumptions!$F$41*12),0),0) -> 2833.3333 | H40: =IF(H$3>Assumptions!$F$7,Assumptions!$F$36/(Assumptions!$F$40*12)+IF(H$3<=Assumptions!$F$7+Assumptions!$F$41*12,Assumptions!$F$37/(Assumptions!$F$41*12),0),0) -> 2833.3333 | I40: =IF(I$3>Assumptions!$F$7,Assumptions!$F$36/(Assumptions!$F$40*12)+IF(I$3<=Assumptions!$F$7+Assumptions!$F$41*12,Assumptions!$F$37/(Assumptions!$F$41*12),0),0) -> 2833.3333 | J40: =IF(J$3>Assumptions!$F$7,Assumptions!$F$36/(Assumptions!$F$40*12)+IF(J$3<=Assumptions!$F$7+Assumptions!$F$41*12,Assumptions!$F$37/(Assumptions!$F$41*12),0),0) -> 2833.3333 | ... BJ40: =IF(BJ$3>Assumptions!$F$7,Assumptions!$F$36/(Assumptions!$F$40*12)+IF(BJ$3<=Assumptions!$F$7+Assumptions!$F$41*12,Assumptions!$F$37/(Assumptions!$F$41*12),0),0) -> 2833.3333
A41: FINANCING
...

Sheet Annual
A1: Youth Pullet-Rearing Enterprise (one group of 10) - Annual statements, Project Years 1-5 (PY = 12 model months from the Sep. start)
A3: ETB | B3: PY1 | C3: PY2 | D3: PY3 | E3: PY4 | F3: PY5 | G3: Total PY1-5
A4: INCOME STATEMENT
A5: Pullet sales | B5: =SUMIF(Monthly!$C$4:$BJ$4,1,Monthly!$C$14:$BJ$14) -> 607500 | C5: =SUMIF(Monthly!$C$4:$BJ$4,2,Monthly!$C$14:$BJ$14) -> 907200 | D5: =SUMIF(Monthly!$C$4:$BJ$4,3,Monthly!$C$14:$BJ$14) -> 1016064 | E5: =SUMIF(Monthly!$C$4:$BJ$4,4,Monthly!$C$14:$BJ$14) -> 1137991.7 | F5: =SUMIF(Monthly!$C$4:$BJ$4,5,Monthly!$C$14:$BJ$14) -> 1274550.7 | G5: =SUM(B5:F5) -> 4943306.4
A6: Total sales revenue | B6: =B5 -> 607500 | C6: =C5 -> 907200 | D6: =D5 -> 1016064 | E6: =E5 -> 1137991.7 | F6: =F5 -> 1274550.7 | G6: =SUM(B6:F6) -> 4943306.4
A7: Day-old chicks | B7: =SUMIF(Monthly!$C$4:$BJ$4,1,Monthly!$C$18:$BJ$18) -> 150000 | C7: =SUMIF(Monthly!$C$4:$BJ$4,2,Monthly!$C$18:$BJ$18) -> 224000 | D7: =SUMIF(Monthly!$C$4:$BJ$4,3,Monthly!$C$18:$BJ$18) -> 250880 | E7: =SUMIF(Monthly!$C$4:$BJ$4,4,Monthly!$C$18:$BJ$18) -> 280985.6 | F7: =SUMIF(Monthly!$C$4:$BJ$4,5,Monthly!$C$18:$BJ$18) -> 314703.87 | G7: =SUM(B7:F7) -> 1220569.5
A8: Feed | B8: =SUMIF(Monthly!$C$4:$BJ$4,1,Monthly!$C$19:$BJ$19) -> 204000 | C8: =SUMIF(Monthly!$C$4:$BJ$4,2,Monthly!$C$19:$BJ$19) -> 304640 | D8: =SUMIF(Monthly!$C$4:$BJ$4,3,Monthly!$C$19:$BJ$19) -> 341196.8 | E8: =SUMIF(Monthly!$C$4:$BJ$4,4,Monthly!$C$19:$BJ$19) -> 382140.42 | F8: =SUMIF(Monthly!$C$4:$BJ$4,5,Monthly!$C$19:$BJ$19) -> 427997.27 | G8: =SUM(B8:F8) -> 1659974.5
A9: Vaccines and medication | B9: =SUMIF(Monthly!$C$4:$BJ$4,1,Monthly!$C$20:$BJ$20) -> 18000 | C9: =SUMIF(Monthly!$C$4:$BJ$4,2,Monthly!$C$20:$BJ$20) -> 26880 | D9: =SUMIF(Monthly!$C$4:$BJ$4,3,Monthly!$C$20:$BJ$20) -> 30105.6 | E9: =SUMIF(Monthly!$C$4:$BJ$4,4,Monthly!$C$20:$BJ$20) -> 33718.272 | F9: =SUMIF(Monthly!$C$4:$BJ$4,5,Monthly!$C$20:$BJ$20) -> 37764.465 | G9: =SUM(B9:F9) -> 146468.34
A10: Brooding energy | B10: =SUMIF(Monthly!$C$4:$BJ$4,1,Monthly!$C$21:$BJ$21) -> 9000 | C10: =SUMIF(Monthly!$C$4:$BJ$4,2,Monthly!$C$21:$BJ$21) -> 13440 | D10: =SUMIF(Monthly!$C$4:$BJ$4,3,Monthly!$C$21:$BJ$21) -> 15052.8 | E10: =SUMIF(Monthly!$C$4:$BJ$4,4,Monthly!$C$21:$BJ$21) -> 16859.136 | F10: =SUMIF(Monthly!$C$4:$BJ$4,5,Monthly!$C$21:$BJ$21) -> 18882.232 | G10: =SUM(B10:F10) -> 73234.168
A11: Litter and disinfectant | B11: =SUMIF(Monthly!$C$4:$BJ$4,1,Monthly!$C$22:$BJ$22) -> 4500 | C11: =SUMIF(Monthly!$C$4:$BJ$4,2,Monthly!$C$22:$BJ$22) -> 6720 | D11: =SUMIF(Monthly!$C$4:$BJ$4,3,Monthly!$C$22:$BJ$22) -> 7526.4 | E11: =SUMIF(Monthly!$C$4:$BJ$4,4,Monthly!$C$22:$BJ$22) -> 8429.568 | F11: =SUMIF(Monthly!$C$4:$BJ$4,5,Monthly!$C$22:$BJ$22) -> 9441.1162 | G11: =SUM(B11:F11) -> 36617.084
A12: Selling and transport | B12: =SUMIF(Monthly!$C$4:$BJ$4,1,Monthly!$C$23:$BJ$23) -> 12000 | C12: =SUMIF(Monthly!$C$4:$BJ$4,2,Monthly!$C$23:$BJ$23) -> 17920 | D12: =SUMIF(Monthly!$C$4:$BJ$4,3,Monthly!$C$23:$BJ$23) -> 20070.4 | E12: =SUMIF(Monthly!$C$4:$BJ$4,4,Monthly!$C$23:$BJ$23) -> 22478.848 | F12: =SUMIF(Monthly!$C$4:$BJ$4,5,Monthly!$C$23:$BJ$23) -> 25176.31 | G12: =SUM(B12:F12) -> 97645.558
A13: Total variable (direct) costs | B13: =B7+B8+B9+B10+B11+B12 -> 397500 | C13: =C7+C8+C9+C10+C11+C12 -> 593600 | D13: =D7+D8+D9+D10+D11+D12 -> 664832 | E13: =E7+E8+E9+E10+E11+E12 -> 744611.84 | F13: =F7+F8+F9+F10+F11+F12 -> 833965.26 | G13: =SUM(B13:F13) -> 3234509.1
A14: Gross margin | B14: =B6-B13 -> 210000 | C14: =C6-C13 -> 313600 | D14: =D6-D13 -> 351232 | E14: =E6-E13 -> 393379.84 | F14: =F6-F13 -> 440585.42 | G14: =SUM(B14:F14) -> 1708797.3
A15: Gross margin % | B15: =IF(B6=0,0,B14/B6) -> 0.34567901 | C15: =IF(C6=0,0,C14/C6) -> 0.34567901 | D15: =IF(D6=0,0,D14/D6) -> 0.34567901 | E15: =IF(E6=0,0,E14/E6) -> 0.34567901 | F15: =IF(F6=0,0,F14/F6) -> 0.34567901
A16: Member duty allowances | B16: =SUMIF(Monthly!$C$4:$BJ$4,1,Monthly!$C$29:$BJ$29) -> 81000 | C16: =SUMIF(Monthly!$C$4:$BJ$4,2,Monthly!$C$29:$BJ$29) -> 120960 | D16: =SUMIF(Monthly!$C$4:$BJ$4,3,Monthly!$C$29:$BJ$29) -> 135475.2 | E16: =SUMIF(Monthly!$C$4:$BJ$4,4,Monthly!$C$29:$BJ$29) -> 151732.22 | F16: =SUMIF(Monthly!$C$4:$BJ$4,5,Monthly!$C$29:$BJ$29) -> 169940.09 | G16: =SUM(B16:F16) -> 659107.51
A17: Water | B17: =SUMIF(Monthly!$C$4:$BJ$4,1,Monthly!$C$30:$BJ$30) -> 5400 | C17: =SUMIF(Monthly!$C$4:$BJ$4,2,Monthly!$C$30:$BJ$30) -> 8064 | D17: =SUMIF(Monthly!$C$4:$BJ$4,3,Monthly!$C$30:$BJ$30) -> 9031.68 | E17: =SUMIF(Monthly!$C$4:$BJ$4,4,Monthly!$C$30:$BJ$30) -> 10115.482 | F17: =SUMIF(Monthly!$C$4:$BJ$4,5,Monthly!$C$30:$BJ$30) -> 11329.339 | G17: =SUM(B17:F17) -> 43940.501
A18: Administration | B18: =SUMIF(Monthly!$C$4:$BJ$4,1,Monthly!$C$31:$BJ$31) -> 7200 | C18: =SUMIF(Monthly!$C$4:$BJ$4,2,Monthly!$C$31:$BJ$31) -> 10752 | D18: =SUMIF(Monthly!$C$4:$BJ$4,3,Monthly!$C$31:$BJ$31) -> 12042.24 | E18: =SUMIF(Monthly!$C$4:$BJ$4,4,Monthly!$C$31:$BJ$31) -> 13487.309 | F18: =SUMIF(Monthly!$C$4:$BJ$4,5,Monthly!$C$31:$BJ$31) -> 15105.786 | G18: =SUM(B18:F18) -> 58587.335
A19: Maintenance | B19: =SUMIF(Monthly!$C$4:$BJ$4,1,Monthly!$C$32:$BJ$32) -> 11062.5 | C19: =SUMIF(Monthly!$C$4:$BJ$4,2,Monthly!$C$32:$BJ$32) -> 16520 | D19: =SUMIF(Monthly!$C$4:$BJ$4,3,Monthly!$C$32:$BJ$32) -> 18502.4 | E19: =SUMIF(Monthly!$C$4:$BJ$4,4,Monthly!$C$32:$BJ$32) -> 20722.688 | F19: =SUMIF(Monthly!$C$4:$BJ$4,5,Monthly!$C$32:$BJ$32) -> 23209.411 | G19: =SUM(B19:F19) -> 90016.999
A20: Registration and licences | B20: =SUMIF(Monthly!$C$4:$BJ$4,1,Monthly!$C$33:$BJ$33) -> 3000 | C20: =SUMIF(Monthly!$C$4:$BJ$4,2,Monthly!$C$33:$BJ$33) -> 2240 | D20: =SUMIF(Monthly!$C$4:$BJ$4,3,Monthly!$C$33:$BJ$33) -> 2508.8 | E20: =SUMIF(Monthly!$C$4:$BJ$4,4,Monthly!$C$33:$BJ$33) -> 2809.856 | F20: =SUMIF(Monthly!$C$4:$BJ$4,5,Monthly!$C$33:$BJ$33) -> 3147.0387 | G20: =SUM(B20:F20) -> 13705.695
A21: Total fixed operating costs | B21: =B16+B17+B18+B19+B20 -> 107662.5 | C21: =C16+C17+C18+C19+C20 -> 158536 | D21: =D16+D17+D18+D19+D20 -> 177560.32 | E21: =E16+E17+E18+E19+E20 -> 198867.56 | F21: =F16+F17+F18+F19+F20 -> 222731.67 | G21: =SUM(B21:F21) -> 865358.04
A22: EBITDA excluding grants | B22: =B14-B21 -> 102337.5 | C22: =C14-C21 -> 155064 | D22: =D14-D21 -> 173671.68 | E22: =E14-E21 -> 194512.28 | F22: =F14-F21 -> 217853.76 | G22: =SUM(B22:F22) -> 843439.22
A23: Depreciation | B23: =SUMIF(Monthly!$C$4:$BJ$4,1,Monthly!$C$40:$BJ$40) -> 25500 | C23: =SUMIF(Monthly!$C$4:$BJ$4,2,Monthly!$C$40:$BJ$40) -> 34000 | D23: =SUMIF(Monthly!$C$4:$BJ$4,3,Monthly!$C$40:$BJ$40) -> 34000 | E23: =SUMIF(Monthly!$C$4:$BJ$4,4,Monthly!$C$40:$BJ$40) -> 34000 | F23: =SUMIF(Monthly!$C$4:$BJ$4,5,Monthly!$C$40:$BJ$40) -> 34000 | G23: =SUM(B23:F23) -> 161500
A24: Operating profit (EBIT) excluding grants | B24: =B22-B23 -> 76837.5 | C24: =C22-C23 -> 121064 | D24: =D22-D23 -> 139671.68 | E24: =E22-E23 -> 160512.28 | F24: =F22-F23 -> 183853.76 | G24: =SUM(B24:F24) -> 681939.22
A25: Interest expense | B25: =SUMIF(Monthly!$C$4:$BJ$4,1,Monthly!$C$44:$BJ$44) -> 14618.491 | C25: =SUMIF(Monthly!$C$4:$BJ$4,2,Monthly!$C$44:$BJ$44) -> 7359.7492 | D25: =SUMIF(Monthly!$C$4:$BJ$4,3,Monthly!$C$44:$BJ$44) -> 6.4028427e-12 | E25: =SUMIF(Monthly!$C$4:$BJ$4,4,Monthly!$C$44:$BJ$44) -> 6.4028427e-12 | F25: =SUMIF(Monthly!$C$4:$BJ$4,5,Monthly!$C$44:$BJ$44) -> 6.4028427e-12 | G25: =SUM(B25:F25) -> 21978.241
A26: Profit before grants and tax | B26: =B24-B25 -> 62219.009 | C26: =C24-C25 -> 113704.25 | D26: =D24-D25 -> 139671.68 | E26: =E24-E25 -> 160512.28 | F26: =F24-F25 -> 183853.76 | G26: =SUM(B26:F26) -> 659960.98
A27: Grant income - in-kind inputs (non-cash, non-recurring) | B27: =SUMIF(Monthly!$C$4:$BJ$4,1,Monthly!$C$25:$BJ$25) -> 57000 | C27: =SUMIF(Monthly!$C$4:$BJ$4,2,Monthly!$C$25:$BJ$25) -> 0 | D27: =SUMIF(Monthly!$C$4:$BJ$4,3,Monthly!$C$25:$BJ$25) -> 0 | E27: =SUMIF(Monthly!$C$4:$BJ$4,4,Monthly!$C$25:$BJ$25) -> 0 | F27: =SUMIF(Monthly!$C$4:$BJ$4,5,Monthly!$C$25:$BJ$25) -> 0 | G27: =SUM(B27:F27) -> 57000
A28: Profit before tax | B28: =B26+B27 -> 119219.01 | C28: =C26+C27 -> 113704.25 | D28: =D26+D27 -> 139671.68 | E28: =E26+E27 -> 160512.28 | F28: =F26+F27 -> 183853.76 | G28: =SUM(B28:F28) -> 716960.98
A29: Business income tax (placeholder rate; to verify) | B29: =MAX(0,B28)*Assumptions!$F$51 -> 11921.901 | C29: =MAX(0,C28)*Assumptions!$F$51 -> 11370.425 | D29: =MAX(0,D28)*Assumptions!$F$51 -> 13967.168 | E29: =MAX(0,E28)*Assumptions!$F$51 -> 16051.228 | F29: =MAX(0,F28)*Assumptions!$F$51 -> 18385.376 | G29: =SUM(B29:F29) -> 71696.098
A30: NET PROFIT | B30: =B28-B29 -> 107297.11 | C30: =C28-C29 -> 102333.83 | D30: =D28-D29 -> 125704.51 | E30: =E28-E29 -> 144461.05 | F30: =F28-F29 -> 165468.38 | G30: =SUM(B30:F30) -> 645264.88
A31: Memo: net profit excluding grant income | B31: =B30-B27 -> 50297.108 | C31: =C30-C27 -> 102333.83 | D31: =D30-D27 -> 125704.51 | E31: =E30-E27 -> 144461.05 | F31: =F30-F27 -> 165468.38 | G31: =SUM(B31:F31) -> 588264.88
A32: Memo: imputed value of unpaid member labour | B32: =SUMIF(Monthly!$C$4:$BJ$4,1,Monthly!$C$35:$BJ$35) -> 63000 | C32: =SUMIF(Monthly!$C$4:$BJ$4,2,Monthly!$C$35:$BJ$35) -> 94080 | D32: =SUMIF(Monthly!$C$4:$BJ$4,3,Monthly!$C$35:$BJ$35) -> 105369.6 | E32: =SUMIF(Monthly!$C$4:$BJ$4,4,Monthly!$C$35:$BJ$35) -> 118013.95 | F32: =SUMIF(Monthly!$C$4:$BJ$4,5,Monthly!$C$35:$BJ$35) -> 132175.63 | G32: =SUM(B32:F32) -> 512639.18
A33: Memo: economic profit after imputing unpaid labour, excl. grants | B33: =B31-B32 -> -12702.892 | C33: =C31-C32 -> 8253.8257 | D33: =D31-D32 -> 20334.912 | E33: =E31-E32 -> 26447.101 | F33: =F31-F32 -> 33292.754 | G33: =SUM(B33:F33) -> 75625.7
A35: CASH FLOW STATEMENT (direct method)
A36: Cash collected from customers | B36: =SUMIF(Monthly!$C$4:$BJ$4,1,Monthly!$C$15:$BJ$15) -> 526500 | C36: =SUMIF(Monthly!$C$4:$BJ$4,2,Monthly!$C$15:$BJ$15) -> 897480 | D36: =SUMIF(Monthly!$C$4:$BJ$4,3,Monthly!$C$15:$BJ$15) -> 1005177.6 | E36: =SUMIF(Monthly!$C$4:$BJ$4,4,Monthly!$C$15:$BJ$15) -> 1125798.9 | F36: =SUMIF(Monthly!$C$4:$BJ$4,5,Monthly!$C$15:$BJ$15) -> 1260894.8 | G36: =SUM(B36:F36) -> 4815851.3
A37: Cash paid: variable costs (net of in-kind grant inputs) | B37: =SUMIF(Monthly!$C$4:$BJ$4,1,Monthly!$C$26:$BJ$26) -> 340500 | C37: =SUMIF(Monthly!$C$4:$BJ$4,2,Monthly!$C$26:$BJ$26) -> 593600 | D37: =SUMIF(Monthly!$C$4:$BJ$4,3,Monthly!$C$26:$BJ$26) -> 664832 | E37: =SUMIF(Monthly!$C$4:$BJ$4,4,Monthly!$C$26:$BJ$26) -> 744611.84 | F37: =SUMIF(Monthly!$C$4:$BJ$4,5,Monthly!$C$26:$BJ$26) -> 833965.26 | G37: =SUM(B37:F37) -> 3177509.1
A38: Cash paid: fixed operating costs | B38: =SUMIF(Monthly!$C$4:$BJ$4,1,Monthly!$C$34:$BJ$34) -> 107662.5 | C38: =SUMIF(Monthly!$C$4:$BJ$4,2,Monthly!$C$34:$BJ$34) -> 158536 | D38: =SUMIF(Monthly!$C$4:$BJ$4,3,Monthly!$C$34:$BJ$34) -> 177560.32 | E38: =SUMIF(Monthly!$C$4:$BJ$4,4,Monthly!$C$34:$BJ$34) -> 198867.56 | F38: =SUMIF(Monthly!$C$4:$BJ$4,5,Monthly!$C$34:$BJ$34) -> 222731.67 | G38: =SUM(B38:F38) -> 865358.04
A39: Interest paid | B39: =SUMIF(Monthly!$C$4:$BJ$4,1,Monthly!$C$44:$BJ$44) -> 14618.491 | C39: =SUMIF(Monthly!$C$4:$BJ$4,2,Monthly!$C$44:$BJ$44) -> 7359.7492 | D39: =SUMIF(Monthly!$C$4:$BJ$4,3,Monthly!$C$44:$BJ$44) -> 6.4028427e-12 | E39: =SUMIF(Monthly!$C$4:$BJ$4,4,Monthly!$C$44:$BJ$44) -> 6.4028427e-12 | F39: =SUMIF(Monthly!$C$4:$BJ$4,5,Monthly!$C$44:$BJ$44) -> 6.4028427e-12 | G39: =SUM(B39:F39) -> 21978.241
A40: Income tax paid | B40: =SUMIF(Monthly!$C$4:$BJ$4,1,Monthly!$C$50:$BJ$50) -> 0 | C40: =SUMIF(Monthly!$C$4:$BJ$4,2,Monthly!$C$50:$BJ$50) -> 11921.901 | D40: =SUMIF(Monthly!$C$4:$BJ$4,3,Monthly!$C$50:$BJ$50) -> 11370.425 | E40: =SUMIF(Monthly!$C$4:$BJ$4,4,Monthly!$C$50:$BJ$50) -> 13967.168 | F40: =SUMIF(Monthly!$C$4:$BJ$4,5,Monthly!$C$50:$BJ$50) -> 16051.228 | G40: =SUM(B40:F40) -> 53310.722
A41: Net cash from operations | B41: =B36-B37-B38-B39-B40 -> 63719.009 | C41: =C36-C37-C38-C39-C40 -> 126062.35 | D41: =D36-D37-D38-D39-D40 -> 151414.85 | E41: =E36-E37-E38-E39-E40 -> 168352.35 | F41: =F36-F37-F38-F39-F40 -> 188146.63 | G41: =SUM(B41:F41) -> 697695.19
A42: Net cash from investing (cash-funded capex) | B42: =SUMIF(Monthly!$C$4:$BJ$4,1,Monthly!$C$53:$BJ$53) -> -30000 | C42: =SUMIF(Monthly!$C$4:$BJ$4,2,Monthly!$C$53:$BJ$53) -> 0 | D42: =SUMIF(Monthly!$C$4:$BJ$4,3,Monthly!$C$53:$BJ$53) -> 0 | E42: =SUMIF(Monthly!$C$4:$BJ$4,4,Monthly!$C$53:$BJ$53) -> 0 | F42: =SUMIF(Monthly!$C$4:$BJ$4,5,Monthly!$C$53:$BJ$53) -> 0 | G42: =SUM(B42:F42) -> -30000
...

Sheet Returns
A1: Youth Pullet-Rearing Enterprise (one group of 10) - Investment appraisal (nominal ETB). Viability test of a single youth enterprise.
B3: PY0 (investment) | C3: PY1 | D3: PY2 | E3: PY3 | F3: PY4 | G3: PY5
A4: A. Full economic view - all investment counted, including grant-funded and in-kind assets; grant income excluded
A5: Investment (all fixed assets at full value) | B5: =-(Assumptions!$F$36+Assumptions!$F$37) -> -295000 | C5: 0 | D5: 0 | E5: 0 | F5: 0 | G5: 0
A6: EBITDA excluding grants | B6: 0 | C6: =Annual!B22 -> 102337.5 | D6: =Annual!C22 -> 155064 | E6: =Annual!D22 -> 173671.68 | F6: =Annual!E22 -> 194512.28 | G6: =Annual!F22 -> 217853.76
A7: Less tax paid | B7: 0 | C7: =-Annual!B40 -> 0 | D7: =-Annual!C40 -> -11921.901 | E7: =-Annual!D40 -> -11370.425 | F7: =-Annual!E40 -> -13967.168 | G7: =-Annual!F40 -> -16051.228
A8: Less increase in working capital (receivables/inventory) | B8: 0 | C8: =-((Annual!B56)-(0)) -> -81000 | D8: =-((Annual!C56)-(Annual!B56)) -> -9720 | E8: =-((Annual!D56)-(Annual!C56)) -> -10886.4 | F8: =-((Annual!E56)-(Annual!D56)) -> -12192.768 | G8: =-((Annual!F56)-(Annual!E56)) -> -13655.9
A9: Residual value: net book value of fixed assets + working capital at end PY5 (conservative) | B9: 0 | C9: 0 | D9: 0 | E9: 0 | F9: 0 | G9: =Annual!F59+Annual!F56 -> 260955.07
A10: Net cash flow | B10: =SUM(B5:B9) -> -295000 | C10: =SUM(C5:C9) -> 21337.5 | D10: =SUM(D5:D9) -> 133422.1 | E10: =SUM(E5:E9) -> 151414.85 | F10: =SUM(F5:F9) -> 168352.35 | G10: =SUM(G5:G9) -> 449101.7
A11: Cumulative net cash flow | B11: =B10 -> -295000 | C11: =B11+C10 -> -273662.5 | D11: =C11+D10 -> -140240.4 | E11: =D11+E10 -> 11174.454 | F11: =E11+F10 -> 179526.8 | G11: =F11+G10 -> 628628.49
A13: B. Enterprise view - grant-funded and in-kind assets and inputs treated as free to the enterprise
A14: Investment funded by the enterprise (cash capex) | B14: =-(Assumptions!$F$37-Assumptions!$F$38) -> -30000 | C14: 0 | D14: 0 | E14: 0 | F14: 0 | G14: 0
A15: EBITDA excl. grants + in-kind grant inputs - tax - change in working capital | B15: 0 | C15: =C6+Annual!B27+C7+C8 -> 78337.5 | D15: =D6+Annual!C27+D7+D8 -> 133422.1 | E15: =E6+Annual!D27+E7+E8 -> 151414.85 | F15: =F6+Annual!E27+F7+F8 -> 168352.35 | G15: =G6+Annual!F27+G7+G8 -> 188146.63
A16: Residual value (as above) | B16: 0 | C16: 0 | D16: 0 | E16: 0 | F16: 0 | G16: =G9 -> 260955.07
A17: Net cash flow | B17: =SUM(B14:B16) -> -30000 | C17: =SUM(C14:C16) -> 78337.5 | D17: =SUM(D14:D16) -> 133422.1 | E17: =SUM(E14:E16) -> 151414.85 | F17: =SUM(F14:F16) -> 168352.35 | G17: =SUM(G14:G16) -> 449101.7
A18: Cumulative net cash flow | B18: =B17 -> -30000 | C18: =B18+C17 -> 48337.5 | D18: =C18+D17 -> 181759.6 | E18: =D18+E17 -> 333174.45 | F18: =E18+F17 -> 501526.8 | G18: =F18+G17 -> 950628.49
A20: Results
A21: Discount rate (nominal ETB; see Assumptions note) | B21: =Assumptions!$F$52 -> 0.25
A22: A. NPV at discount rate | B22: =B10+NPV(Assumptions!$F$52,C10:G10) -> 101103.31
A23: A. IRR | B23: =IFERROR(IRR(B10:G10),"not defined") -> 0.35834802
A24: A. Payback (years from PY0) | B24: =IF(G11<0,"> 5 years",COUNTIF(C11:G11,"<0")+(-INDEX(B11:G11,1,COUNTIF(C11:G11,"<0")+1))/INDEX(C10:G10,1,COUNTIF(C11:G11,"<0")+1)) -> 2.9261998
A25: B. NPV at discount rate | B25: =B17+NPV(Assumptions!$F$52,C17:G17) -> 411703.31
A26: B. IRR | B26: =IFERROR(IRR(B17:G17),"not defined") -> 3.1201684
A27: B. Payback (years from PY0) | B27: =IF(G18<0,"> 5 years",COUNTIF(C18:G18,"<0")+(-INDEX(B18:G18,1,COUNTIF(C18:G18,"<0")+1))/INDEX(C17:G17,1,COUNTIF(C18:G18,"<0")+1)) -> 0.38295835
A29: Notes: PY0 investment is placed at the start of PY1 for simplicity (actual capex occurs in model month 3-4). Residual value is book value, not market value. All flows are nominal ETB: prices and costs escalate annually at the separate price and cost escalation rates on the Assumptions sheet, consistent with a nominal discount rate.

Sheet Unit_BreakEven
A1: Unit economics and break-even (PY1 prices, active scenario)
A3: Variable cost per bird PLACED (DOC + feed + vaccine + per-batch costs / batch) | B3: =Assumptions!$F$17+Assumptions!$F$14*Assumptions!$F$18+Assumptions!$F$19+(Assumptions!$F$20+Assumptions!$F$21+Assumptions!$F$22)/Assumptions!$F$12 -> 265
A4: Variable cost per pullet SOLD (divide by survival) | B4: =B3/(1-Assumptions!$F$13) -> 294.44444
A5: Selling price per pullet | B5: =Assumptions!$F$23 -> 450
A6: Contribution per pullet sold | B6: =B5-B4 -> 155.55556
A7: Contribution margin % | B7: =IF(B5=0,0,B6/B5) -> 0.34567901
A8: Of which feed per pullet sold | B8: =Assumptions!$F$14*Assumptions!$F$18/(1-Assumptions!$F$13) -> 151.11111
A9: Of which DOC per pullet sold | B9: =Assumptions!$F$17/(1-Assumptions!$F$13) -> 111.11111
A10: Fixed cash costs, PY2 (deflated to PY1 prices) | B10: =Annual!C21/(1+Assumptions!$F$26) -> 141550
A11: Depreciation, PY2 | B11: =Annual!C23 -> 34000
A12: Interest, PY2 | B12: =Annual!C25 -> 7359.7492
A13: Accounting break-even: pullets sold per year | B13: =IF(B6<=0,"no break-even",(B10+B11+B12)/B6) -> 1175.8484
A14: Accounting break-even: revenue per year (PY1 prices) | B14: =IF(ISNUMBER(B13),B13*B5,"n/a") -> 529131.77
A15: Accounting break-even: batches per year at planned batch size | B15: =IF(ISNUMBER(B13),B13/(Assumptions!$F$12*(1-Assumptions!$F$13)),"n/a") -> 2.6129964
A16: Cash break-even incl. loan principal (PY2): pullets per year | B16: =IF(B6<=0,"no break-even",(B10+B12+Annual!C45)/B6) -> 1374.7598
A17: Planned pullets sold per year at full operation (PY2) | B17: =Annual!C79 -> 1800
A18: Margin of safety (planned vs accounting break-even) | B18: =IF(ISNUMBER(B13),(B17-B13)/B17,"n/a") -> 0.3467509
A19: Break-even PRICE per pullet at planned PY2 volume (PY1 prices) | B19: =B4+(B10+B11+B12)/B17 -> 396.06097
A20: Break-even SURVIVAL rate at planned price and placements (PY1 prices) | B20: =(B3*Annual!C78+B10+B11+B12)/(Annual!C78*B5) -> 0.79212194
